Workbook

Sheet מחשבון
A1: מחשבון השקעה ורכישת דירה — 2026
A2: הזן ערכים בתאים הצהובים בלבד. כל השאר מתחשב אוטומטית. ראה גיליונות נוספים בתחתית.
A4: 🔹 נתוני קלט
A5: מחיר הדירה (₪) | B5: 2000000
A6: סוג רכישה | B6: דירה יחידה
A7: אחוז מימון רצוי | B7: 0.75
A8: תקופת המשכנתא (שנים) | B8: 25
A9: ריבית שנתית | B9: 0.048
A10: שכר דירה חודשי צפוי (₪) | B10: 6000
A11: עלות תיווך (%) | B11: 0.02
A12: שכ"ט עו"ד (%) | B12: 0.005
A13: עלויות נוספות (₪) | B13: 0
A14: מע"מ על שירותים | B14: 0.18
A15: יחס החזר מקס' | B15: 0.33
A17: 🔹 מס רכישה ועלויות נלוות
A18: מס רכישה — אם דירה יחידה | B18: =SUM(נתונים!D5:D9) -> 743.925
A19: מס רכישה — אם דירה נוספת | B19: =SUM(נתונים!D13:D14) -> 160000
A20: מס רכישה לפי הסוג שנבחר | B20: =IF(B6="דירה להשקעה",B19,B18) -> 743.925
A21: דמי תיווך (כולל מע"מ) | B21: =B5*B11*(1+B14) -> 47200
A22: שכ"ט עו"ד (כולל מע"מ) | B22: =B5*B12*(1+B14) -> 11800
A23: עלויות נוספות | B23: =B13 -> 0
A24: סך עלויות נלוות | B24: =B20+B21+B22+B23 -> 59743.925
A26: 🔹 מימון, משכנתא והון עצמי
A27: תקרת מימון מותרת | B27: =IF(B6="דירה להשקעה",נתונים!B19,IF(B6="משפר דיור",נתונים!B18,נתונים!B17)) -> 0.75
A28: אחוז מימון בפועל | B28: =MIN(B7,B27) -> 0.75
A29: סכום המשכנתא | B29: =B5*B28 -> 1500000
A30: הון עצמי נדרש (כולל נלוות) | B30: =B5-B29+B24 -> 559743.93
A31: החזר חודשי | B31: =IF(B29>0,PMT(B9/12,B8*12,-B29),0) -> 8594.9544
A32: סך תשלום לאורך התקופה | B32: =B31*B8*12 -> 2578486.3
A33: סך ריבית שתשולם | B33: =B32-B29 -> 1078486.3
A34: הכנסה פנויה נדרשת (אומדן) | B34: =IF(B15>0,B31/B15,0) -> 26045.316
A36: 🔹 תשואה ותזרים
A37: הכנסה שנתית משכירות | B37: =B10*12 -> 72000
A38: עלות העסקה הכוללת | B38: =B5+B24 -> 2059743.9
A39: תשואה ברוטו (על המחיר) | B39: =IF(B5>0,B37/B5,0) -> 0.036
A40: תשואה ברוטו (על העלות הכוללת) | B40: =IF(B38>0,B37/B38,0) -> 0.034955802
A41: תזרים חודשי נטו | B41: =B10-B31 -> -2594.9544
A42: תזרים שנתי נטו | B42: =B41*12 -> -31139.453
A43: תשואה על ההון (Cash-on-Cash) | B43: =IF(B30>0,B42/B30,0) -> -0.055631605
A45: 🔹 הוצאות שוטפות ומס שכירות
...

Sheet נתונים
A1: פרמטרים והגדרות — לעריכה
A3: מס רכישה — דירה יחידה (2026)
A4: מ- (₪) | B4: עד (₪) | C4: שיעור | D4: מס במדרגה
A5: 0 | B5: 1978745 | C5: 0 | D5: =MAX(0,MIN(מחשבון!$B$5,B5)-A5)*C5 -> 0
A6: 1978745 | B6: 2347040 | C6: 0.035 | D6: =MAX(0,MIN(מחשבון!$B$5,B6)-A6)*C6 -> 743.925
A7: 2347040 | B7: 6055070 | C7: 0.05 | D7: =MAX(0,MIN(מחשבון!$B$5,B7)-A7)*C7 -> 0
A8: 6055070 | B8: 20183565 | C8: 0.08 | D8: =MAX(0,MIN(מחשבון!$B$5,B8)-A8)*C8 -> 0
A9: 20183565 | B9: 999999999 | C9: 0.1 | D9: =MAX(0,MIN(מחשבון!$B$5,B9)-A9)*C9 -> 0
A11: מס רכישה — דירה נוספת/השקעה (2026)
A12: מ- (₪) | B12: עד (₪) | C12: שיעור | D12: מס במדרגה
A13: 0 | B13: 6055070 | C13: 0.08 | D13: =MAX(0,MIN(מחשבון!$B$5,B13)-A13)*C13 -> 160000
A14: 6055070 | B14: 999999999 | C14: 0.1 | D14: =MAX(0,MIN(מחשבון!$B$5,B14)-A14)*C14 -> 0
A16: תקרות מימון (LTV) — בנק ישראל
A17: דירה יחידה / ראשונה | B17: 0.75
A18: משפר דיור | B18: 0.7
A19: דירה להשקעה / נוספת | B19: 0.5
A21: פרמטרים נוספים
A22: שיעור מס שבח (השקעה) | B22: 0.25
A23: גידול שכר דירה שנתי (ברירת מחדל) | B23: 0.03
A24: עליית ערך נכס שנתית (ברירת מחדל) | B24: 0.035
A25: מס יסף (הכנסה גבוהה) | B25: 0.05
A26: תקרת פטור דירה יחידה (מס שבח) | B26: 5008000
A27: אינפלציה שנתית (ברירת מחדל) | B27: 0.025
A28: תקרת פטור שכירות חודשי | B28: 5654
A29: שיעור מס שכירות מחזור (10%) | B29: 0.1
A30: מדרגת מס שולי שכירות | B30: 0.31
A31: שיעור פחת שנתי (מבנה) | B31: 0.02
A32: מגבלת ריבית משתנה (בנק ישראל) | B32: 0.66666667

Sheet לוח סילוקין
A1: לוח סילוקין שנתי
A2: מבוסס על נתוני גיליון 'מחשבון' (סכום משכנתא, ריבית, תקופה).
A4: שנה | B4: יתרת פתיחה | C4: תשלום שנתי | D4: מתוכו ריבית | E4: מתוכו קרן | F4: יתרת סגירה
A5: 1 | B5: =IF(1>מחשבון!$B$8,0,מחשבון!$B$29) -> 1500000 | C5: =IF(1>מחשבון!$B$8,0,IF(F5=0,E5+ (B5*(מחשבון!$B$9)),מחשבון!$B$31*12)) -> 103139.45 | D5: =MAX(0,C5-E5) -> 71305.715 | E5: =B5-F5 -> 31833.738 | F5: =IF(1>מחשבון!$B$8,0,IF(מחשבון!$B$9=0,MAX(0,B5-מחשבון!$B$31*12),MAX(0,B5*(1+מחשבון!$B$9/12)^12-מחשבון!$B$31*(((1+מחשבון!$B$9/12)^12-1)/(מחשבון!$B$9/12))))) -> 1468166.3
A6: 2 | B6: =IF(2>מחשבון!$B$8,0,F5) -> 1468166.3 | C6: =IF(2>מחשבון!$B$8,0,IF(F6=0,E6+ (B6*(מחשבון!$B$9)),מחשבון!$B$31*12)) -> 103139.45 | D6: =MAX(0,C6-E6) -> 69743.627 | E6: =B6-F6 -> 33395.826 | F6: =IF(2>מחשבון!$B$8,0,IF(מחשבון!$B$9=0,MAX(0,B6-מחשבון!$B$31*12),MAX(0,B6*(1+מחשבון!$B$9/12)^12-מחשבון!$B$31*(((1+מחשבון!$B$9/12)^12-1)/(מחשבון!$B$9/12))))) -> 1434770.4
A7: 3 | B7: =IF(3>מחשבון!$B$8,0,F6) -> 1434770.4 | C7: =IF(3>מחשבון!$B$8,0,IF(F7=0,E7+ (B7*(מחשבון!$B$9)),מחשבון!$B$31*12)) -> 103139.45 | D7: =MAX(0,C7-E7) -> 68104.887 | E7: =B7-F7 -> 35034.566 | F7: =IF(3>מחשבון!$B$8,0,IF(מחשבון!$B$9=0,MAX(0,B7-מחשבון!$B$31*12),MAX(0,B7*(1+מחשבון!$B$9/12)^12-מחשבון!$B$31*(((1+מחשבון!$B$9/12)^12-1)/(מחשבון!$B$9/12))))) -> 1399735.9
A8: 4 | B8: =IF(4>מחשבון!$B$8,0,F7) -> 1399735.9 | C8: =IF(4>מחשבון!$B$8,0,IF(F8=0,E8+ (B8*(מחשבון!$B$9)),מחשבון!$B$31*12)) -> 103139.45 | D8: =MAX(0,C8-E8) -> 66385.733 | E8: =B8-F8 -> 36753.72 | F8: =IF(4>מחשבון!$B$8,0,IF(מחשבון!$B$9=0,MAX(0,B8-מחשבון!$B$31*12),MAX(0,B8*(1+מחשבון!$B$9/12)^12-מחשבון!$B$31*(((1+מחשבון!$B$9/12)^12-1)/(מחשבון!$B$9/12))))) -> 1362982.1
A9: 5 | B9: =IF(5>מחשבון!$B$8,0,F8) -> 1362982.1 | C9: =IF(5>מחשבון!$B$8,0,IF(F9=0,E9+ (B9*(מחשבון!$B$9)),מחשבון!$B$31*12)) -> 103139.45 | D9: =MAX(0,C9-E9) -> 64582.221 | E9: =B9-F9 -> 38557.232 | F9: =IF(5>מחשבון!$B$8,0,IF(מחשבון!$B$9=0,MAX(0,B9-מחשבון!$B$31*12),MAX(0,B9*(1+מחשבון!$B$9/12)^12-מחשבון!$B$31*(((1+מחשבון!$B$9/12)^12-1)/(מחשבון!$B$9/12))))) -> 1324424.9
A10: 6 | B10: =IF(6>מחשבון!$B$8,0,F9) -> 1324424.9 | C10: =IF(6>מחשבון!$B$8,0,IF(F10=0,E10+ (B10*(מחשבון!$B$9)),מחשבון!$B$31*12)) -> 103139.45 | D10: =MAX(0,C10-E10) -> 62690.209 | E10: =B10-F10 -> 40449.244 | F10: =IF(6>מחשבון!$B$8,0,IF(מחשבון!$B$9=0,MAX(0,B10-מחשבון!$B$31*12),MAX(0,B10*(1+מחשבון!$B$9/12)^12-מחשבון!$B$31*(((1+מחשבון!$B$9/12)^12-1)/(מחשבון!$B$9/12))))) -> 1283975.7
A11: 7 | B11: =IF(7>מחשבון!$B$8,0,F10) -> 1283975.7 | C11: =IF(7>מחשבון!$B$8,0,IF(F11=0,E11+ (B11*(מחשבון!$B$9)),מחשבון!$B$31*12)) -> 103139.45 | D11: =MAX(0,C11-E11) -> 60705.356 | E11: =B11-F11 -> 42434.097 | F11: =IF(7>מחשבון!$B$8,0,IF(מחשבון!$B$9=0,MAX(0,B11-מחשבון!$B$31*12),MAX(0,B11*(1+מחשבון!$B$9/12)^12-מחשבון!$B$31*(((1+מחשבון!$B$9/12)^12-1)/(מחשבון!$B$9/12))))) -> 1241541.6
A12: 8 | B12: =IF(8>מחשבון!$B$8,0,F11) -> 1241541.6 | C12: =IF(8>מחשבון!$B$8,0,IF(F12=0,E12+ (B12*(מחשבון!$B$9)),מחשבון!$B$31*12)) -> 103139.45 | D12: =MAX(0,C12-E12) -> 58623.107 | E12: =B12-F12 -> 44516.347 | F12: =IF(8>מחשבון!$B$8,0,IF(מחשבון!$B$9=0,MAX(0,B12-מחשבון!$B$31*12),MAX(0,B12*(1+מחשבון!$B$9/12)^12-מחשבון!$B$31*(((1+מחשבון!$B$9/12)^12-1)/(מחשבון!$B$9/12))))) -> 1197025.2
A13: 9 | B13: =IF(9>מחשבון!$B$8,0,F12) -> 1197025.2 | C13: =IF(9>מחשבון!$B$8,0,IF(F13=0,E13+ (B13*(מחשבון!$B$9)),מחשבון!$B$31*12)) -> 103139.45 | D13: =MAX(0,C13-E13) -> 56438.68 | E13: =B13-F13 -> 46700.773 | F13: =IF(9>מחשבון!$B$8,0,IF(מחשבון!$B$9=0,MAX(0,B13-מחשבון!$B$31*12),MAX(0,B13*(1+מחשבון!$B$9/12)^12-מחשבון!$B$31*(((1+מחשבון!$B$9/12)^12-1)/(מחשבון!$B$9/12))))) -> 1150324.5
A14: 10 | B14: =IF(10>מחשבון!$B$8,0,F13) -> 1150324.5 | C14: =IF(10>מחשבון!$B$8,0,IF(F14=0,E14+ (B14*(מחשבון!$B$9)),מחשבון!$B$31*12)) -> 103139.45 | D14: =MAX(0,C14-E14) -> 54147.064 | E14: =B14-F14 -> 48992.39 | F14: =IF(10>מחשבון!$B$8,0,IF(מחשבון!$B$9=0,MAX(0,B14-מחשבון!$B$31*12),MAX(0,B14*(1+מחשבון!$B$9/12)^12-מחשבון!$B$31*(((1+מחשבון!$B$9/12)^12-1)/(מחשבון!$B$9/12))))) -> 1101332.1
A15: 11 | B15: =IF(11>מחשבון!$B$8,0,F14) -> 1101332.1 | C15: =IF(11>מחשבון!$B$8,0,IF(F15=0,E15+ (B15*(מחשבון!$B$9)),מחשבון!$B$31*12)) -> 103139.45 | D15: =MAX(0,C15-E15) -> 51742.997 | E15: =B15-F15 -> 51396.456 | F15: =IF(11>מחשבון!$B$8,0,IF(מחשבון!$B$9=0,MAX(0,B15-מחשבון!$B$31*12),MAX(0,B15*(1+מחשבון!$B$9/12)^12-מחשבון!$B$31*(((1+מחשבון!$B$9/12)^12-1)/(מחשבון!$B$9/12))))) -> 1049935.6
A16: 12 | B16: =IF(12>מחשבון!$B$8,0,F15) -> 1049935.6 | C16: =IF(12>מחשבון!$B$8,0,IF(F16=0,E16+ (B16*(מחשבון!$B$9)),מחשבון!$B$31*12)) -> 103139.45 | D16: =MAX(0,C16-E16) -> 49220.962 | E16: =B16-F16 -> 53918.491 | F16: =IF(12>מחשבון!$B$8,0,IF(מחשבון!$B$9=0,MAX(0,B16-מחשבון!$B$31*12),MAX(0,B16*(1+מחשבון!$B$9/12)^12-מחשבון!$B$31*(((1+מחשבון!$B$9/12)^12-1)/(מחשבון!$B$9/12))))) -> 996017.12
A17: 13 | B17: =IF(13>מחשבון!$B$8,0,F16) -> 996017.12 | C17: =IF(13>מחשבון!$B$8,0,IF(F17=0,E17+ (B17*(מחשבון!$B$9)),מחשבון!$B$31*12)) -> 103139.45 | D17: =MAX(0,C17-E17) -> 46575.171 | E17: =B17-F17 -> 56564.283 | F17: =IF(13>מחשבון!$B$8,0,IF(מחשבון!$B$9=0,MAX(0,B17-מחשבון!$B$31*12),MAX(0,B17*(1+מחשבון!$B$9/12)^12-מחשבון!$B$31*(((1+מחשבון!$B$9/12)^12-1)/(מחשבון!$B$9/12))))) -> 939452.84
A18: 14 | B18: =IF(14>מחשבון!$B$8,0,F17) -> 939452.84 | C18: =IF(14>מחשבון!$B$8,0,IF(F18=0,E18+ (B18*(מחשבון!$B$9)),מחשבון!$B$31*12)) -> 103139.45 | D18: =MAX(0,C18-E18) -> 43799.549 | E18: =B18-F18 -> 59339.904 | F18: =IF(14>מחשבון!$B$8,0,IF(מחשבון!$B$9=0,MAX(0,B18-מחשבון!$B$31*12),MAX(0,B18*(1+מחשבון!$B$9/12)^12-מחשבון!$B$31*(((1+מחשבון!$B$9/12)^12-1)/(מחשבון!$B$9/12))))) -> 880112.93
A19: 15 | B19: =IF(15>מחשבון!$B$8,0,F18) -> 880112.93 | C19: =IF(15>מחשבון!$B$8,0,IF(F19=0,E19+ (B19*(מחשבון!$B$9)),מחשבון!$B$31*12)) -> 103139.45 | D19: =MAX(0,C19-E19) -> 40887.728 | E19: =B19-F19 -> 62251.725 | F19: =IF(15>מחשבון!$B$8,0,IF(מחשבון!$B$9=0,MAX(0,B19-מחשבון!$B$31*12),MAX(0,B19*(1+מחשבון!$B$9/12)^12-מחשבון!$B$31*(((1+מחשבון!$B$9/12)^12-1)/(מחשבון!$B$9/12))))) -> 817861.21
A20: 16 | B20: =IF(16>מחשבון!$B$8,0,F19) -> 817861.21 | C20: =IF(16>מחשבון!$B$8,0,IF(F20=0,E20+ (B20*(מחשבון!$B$9)),מחשבון!$B$31*12)) -> 103139.45 | D20: =MAX(0,C20-E20) -> 37833.023 | E20: =B20-F20 -> 65306.43 | F20: =IF(16>מחשבון!$B$8,0,IF(מחשבון!$B$9=0,MAX(0,B20-מחשבון!$B$31*12),MAX(0,B20*(1+מחשבון!$B$9/12)^12-מחשבון!$B$31*(((1+מחשבון!$B$9/12)^12-1)/(מחשבון!$B$9/12))))) -> 752554.78
A21: 17 | B21: =IF(17>מחשבון!$B$8,0,F20) -> 752554.78 | C21: =IF(17>מחשבון!$B$8,0,IF(F21=0,E21+ (B21*(מחשבון!$B$9)),מחשבון!$B$31*12)) -> 103139.45 | D21: =MAX(0,C21-E21) -> 34628.423 | E21: =B21-F21 -> 68511.03 | F21: =IF(17>מחשבון!$B$8,0,IF(מחשבון!$B$9=0,MAX(0,B21-מחשבון!$B$31*12),MAX(0,B21*(1+מחשבון!$B$9/12)^12-מחשבון!$B$31*(((1+מחשבון!$B$9/12)^12-1)/(מחשבון!$B$9/12))))) -> 684043.75
A22: 18 | B22: =IF(18>מחשבון!$B$8,0,F21) -> 684043.75 | C22: =IF(18>מחשבון!$B$8,0,IF(F22=0,E22+ (B22*(מחשבון!$B$9)),מחשבון!$B$31*12)) -> 103139.45 | D22: =MAX(0,C22-E22) -> 31266.572 | E22: =B22-F22 -> 71872.881 | F22: =IF(18>מחשבון!$B$8,0,IF(מחשבון!$B$9=0,MAX(0,B22-מחשבון!$B$31*12),MAX(0,B22*(1+מחשבון!$B$9/12)^12-מחשבון!$B$31*(((1+מחשבון!$B$9/12)^12-1)/(מחשבון!$B$9/12))))) -> 612170.87
A23: 19 | B23: =IF(19>מחשבון!$B$8,0,F22) -> 612170.87 | C23: =IF(19>מחשבון!$B$8,0,IF(F23=0,E23+ (B23*(מחשבון!$B$9)),מחשבון!$B$31*12)) -> 103139.45 | D23: =MAX(0,C23-E23) -> 27739.755 | E23: =B23-F23 -> 75399.698 | F23: =IF(19>מחשבון!$B$8,0,IF(מחשבון!$B$9=0,MAX(0,B23-מחשבון!$B$31*12),MAX(0,B23*(1+מחשבון!$B$9/12)^12-מחשבון!$B$31*(((1+מחשבון!$B$9/12)^12-1)/(מחשבון!$B$9/12))))) -> 536771.17
A24: 20 | B24: =IF(20>מחשבון!$B$8,0,F23) -> 536771.17 | C24: =IF(20>מחשבון!$B$8,0,IF(F24=0,E24+ (B24*(מחשבון!$B$9)),מחשבון!$B$31*12)) -> 103139.45 | D24: =MAX(0,C24-E24) -> 24039.876 | E24: =B24-F24 -> 79099.577 | F24: =IF(20>מחשבון!$B$8,0,IF(מחשבון!$B$9=0,MAX(0,B24-מחשבון!$B$31*12),MAX(0,B24*(1+מחשבון!$B$9/12)^12-מחשבון!$B$31*(((1+מחשבון!$B$9/12)^12-1)/(מחשבון!$B$9/12))))) -> 457671.59
A25: 21 | B25: =IF(21>מחשבון!$B$8,0,F24) -> 457671.59 | C25: =IF(21>מחשבון!$B$8,0,IF(F25=0,E25+ (B25*(מחשבון!$B$9)),מחשבון!$B$31*12)) -> 103139.45 | D25: =MAX(0,C25-E25) -> 20158.444 | E25: =B25-F25 -> 82981.009 | F25: =IF(21>מחשבון!$B$8,0,IF(מחשבון!$B$9=0,MAX(0,B25-מחשבון!$B$31*12),MAX(0,B25*(1+מחשבון!$B$9/12)^12-מחשבון!$B$31*(((1+מחשבון!$B$9/12)^12-1)/(מחשבון!$B$9/12))))) -> 374690.58
A26: 22 | B26: =IF(22>מחשבון!$B$8,0,F25) -> 374690.58 | C26: =IF(22>מחשבון!$B$8,0,IF(F26=0,E26+ (B26*(מחשבון!$B$9)),מחשבון!$B$31*12)) -> 103139.45 | D26: =MAX(0,C26-E26) -> 16086.548 | E26: =B26-F26 -> 87052.905 | F26: =IF(22>מחשבון!$B$8,0,IF(מחשבון!$B$9=0,MAX(0,B26-מחשבון!$B$31*12),MAX(0,B26*(1+מחשבון!$B$9/12)^12-מחשבון!$B$31*(((1+מחשבון!$B$9/12)^12-1)/(מחשבון!$B$9/12))))) -> 287637.68
A27: 23 | B27: =IF(23>מחשבון!$B$8,0,F26) -> 287637.68 | C27: =IF(23>מחשבון!$B$8,0,IF(F27=0,E27+ (B27*(מחשבון!$B$9)),מחשבון!$B$31*12)) -> 103139.45 | D27: =MAX(0,C27-E27) -> 11814.844 | E27: =B27-F27 -> 91324.609 | F27: =IF(23>מחשבון!$B$8,0,IF(מחשבון!$B$9=0,MAX(0,B27-מחשבון!$B$31*12),MAX(0,B27*(1+מחשבון!$B$9/12)^12-מחשבון!$B$31*(((1+מחשבון!$B$9/12)^12-1)/(מחשבון!$B$9/12))))) -> 196313.07
A28: 24 | B28: =IF(24>מחשבון!$B$8,0,F27) -> 196313.07 | C28: =IF(24>מחשבון!$B$8,0,IF(F28=0,E28+ (B28*(מחשבון!$B$9)),מחשבון!$B$31*12)) -> 103139.45 | D28: =MAX(0,C28-E28) -> 7333.5268 | E28: =B28-F28 -> 95805.926 | F28: =IF(24>מחשבון!$B$8,0,IF(מחשבון!$B$9=0,MAX(0,B28-מחשבון!$B$31*12),MAX(0,B28*(1+מחשבון!$B$9/12)^12-מחשבון!$B$31*(((1+מחשבון!$B$9/12)^12-1)/(מחשבון!$B$9/12))))) -> 100507.14
A29: 25 | B29: =IF(25>מחשבון!$B$8,0,F28) -> 100507.14 | C29: =IF(25>מחשבון!$B$8,0,IF(F29=0,E29+ (B29*(מחשבון!$B$9)),מחשבון!$B$31*12)) -> 105331.49 | D29: =MAX(0,C29-E29) -> 4824.3429 | E29: =B29-F29 -> 100507.14 | F29: =IF(25>מחשבון!$B$8,0,IF(מחשבון!$B$9=0,MAX(0,B29-מחשבון!$B$31*12),MAX(0,B29*(1+מחשבון!$B$9/12)^12-מחשבון!$B$31*(((1+מחשבון!$B$9/12)^12-1)/(מחשבון!$B$9/12))))) -> 0
A30: 26 | B30: =IF(26>מחשבון!$B$8,0,F29) -> 0 | C30: =IF(26>מחשבון!$B$8,0,IF(F30=0,E30+ (B30*(מחשבון!$B$9)),מחשבון!$B$31*12)) -> 0 | D30: =MAX(0,C30-E30) -> 0 | E30: =B30-F30 -> 0 | F30: =IF(26>מחשבון!$B$8,0,IF(מחשבון!$B$9=0,MAX(0,B30-מחשבון!$B$31*12),MAX(0,B30*(1+מחשבון!$B$9/12)^12-מחשבון!$B$31*(((1+מחשבון!$B$9/12)^12-1)/(מחשבון!$B$9/12))))) -> 0
A31: 27 | B31: =IF(27>מחשבון!$B$8,0,F30) -> 0 | C31: =IF(27>מחשבון!$B$8,0,IF(F31=0,E31+ (B31*(מחשבון!$B$9)),מחשבון!$B$31*12)) -> 0 | D31: =MAX(0,C31-E31) -> 0 | E31: =B31-F31 -> 0 | F31: =IF(27>מחשבון!$B$8,0,IF(מחשבון!$B$9=0,MAX(0,B31-מחשבון!$B$31*12),MAX(0,B31*(1+מחשבון!$B$9/12)^12-מחשבון!$B$31*(((1+מחשבון!$B$9/12)^12-1)/(מחשבון!$B$9/12))))) -> 0
A32: 28 | B32: =IF(28>מחשבון!$B$8,0,F31) -> 0 | C32: =IF(28>מחשבון!$B$8,0,IF(F32=0,E32+ (B32*(מחשבון!$B$9)),מחשבון!$B$31*12)) -> 0 | D32: =MAX(0,C32-E32) -> 0 | E32: =B32-F32 -> 0 | F32: =IF(28>מחשבון!$B$8,0,IF(מחשבון!$B$9=0,MAX(0,B32-מחשבון!$B$31*12),MAX(0,B32*(1+מחשבון!$B$9/12)^12-מחשבון!$B$31*(((1+מחשבון!$B$9/12)^12-1)/(מחשבון!$B$9/12))))) -> 0
A33: 29 | B33: =IF(29>מחשבון!$B$8,0,F32) -> 0 | C33: =IF(29>מחשבון!$B$8,0,IF(F33=0,E33+ (B33*(מחשבון!$B$9)),מחשבון!$B$31*12)) -> 0 | D33: =MAX(0,C33-E33) -> 0 | E33: =B33-F33 -> 0 | F33: =IF(29>מחשבון!$B$8,0,IF(מחשבון!$B$9=0,MAX(0,B33-מחשבון!$B$31*12),MAX(0,B33*(1+מחשבון!$B$9/12)^12-מחשבון!$B$31*(((1+מחשבון!$B$9/12)^12-1)/(מחשבון!$B$9/12))))) -> 0
A34: 30 | B34: =IF(30>מחשבון!$B$8,0,F33) -> 0 | C34: =IF(30>מחשבון!$B$8,0,IF(F34=0,E34+ (B34*(מחשבון!$B$9)),מחשבון!$B$31*12)) -> 0 | D34: =MAX(0,C34-E34) -> 0 | E34: =B34-F34 -> 0 | F34: =IF(30>מחשבון!$B$8,0,IF(מחשבון!$B$9=0,MAX(0,B34-מחשבון!$B$31*12),MAX(0,B34*(1+מחשבון!$B$9/12)^12-מחשבון!$B$31*(((1+מחשבון!$B$9/12)^12-1)/(מחשבון!$B$9/12))))) -> 0
A35: סה"כ | C35: =SUM(C5:C34) -> 2580678.4 | D35: =SUM(D5:D34) -> 1080678.4 | E35: =SUM(E5:E34) -> 1500000

Sheet תחזית ומכירה
A1: תחזית רב-שנתית ומכירה (כולל מס שבח)
A2: מודל החזקה ומכירה. שנה ושיעורי גידול ניתנים לעריכה (צהוב).
A4: 🔹 הנחות
A5: גידול שכר דירה שנתי | B5: =נתונים!B23 -> 0.03
A6: עליית ערך הנכס שנתית | B6: =נתונים!B24 -> 0.035
A7: שנת מכירה (כמה שנים מחזיקים) | B7: 10
A8: עלות מכירה (תיווך וכד') % | B8: 0.02
A9: פטור ממס שבח? | B9: לא
A11: 🔹 טבלה שנתית
A12: שנה | B12: ערך הנכס | C12: שכר דירה שנתי | D12: תזרים נטו שנתי | E12: יתרת משכנתא | F12: הון עצמי בנכס
A13: 1 | B13: =מחשבון!$B$5*(1+$B$6)^1 -> 2070000 | C13: =מחשבון!$B$37*(1+$B$5)^(1-1) -> 72000 | D13: =C13-IF(1>מחשבון!$B$8,0,מחשבון!$B$31*12) -> -31139.453 | E13: =INDEX('לוח סילוקין'!$F$5:$F$34,1) -> 1468166.3 | F13: =B13-E13 -> 601833.74
A14: 2 | B14: =מחשבון!$B$5*(1+$B$6)^2 -> 2142450 | C14: =מחשבון!$B$37*(1+$B$5)^(2-1) -> 74160 | D14: =C14-IF(2>מחשבון!$B$8,0,מחשבון!$B$31*12) -> -28979.453 | E14: =INDEX('לוח סילוקין'!$F$5:$F$34,2) -> 1434770.4 | F14: =B14-E14 -> 707679.56
A15: 3 | B15: =מחשבון!$B$5*(1+$B$6)^3 -> 2217435.8 | C15: =מחשבון!$B$37*(1+$B$5)^(3-1) -> 76384.8 | D15: =C15-IF(3>מחשבון!$B$8,0,מחשבון!$B$31*12) -> -26754.653 | E15: =INDEX('לוח סילוקין'!$F$5:$F$34,3) -> 1399735.9 | F15: =B15-E15 -> 817699.88
A16: 4 | B16: =מחשבון!$B$5*(1+$B$6)^4 -> 2295046 | C16: =מחשבון!$B$37*(1+$B$5)^(4-1) -> 78676.344 | D16: =C16-IF(4>מחשבון!$B$8,0,מחשבון!$B$31*12) -> -24463.109 | E16: =INDEX('לוח סילוקין'!$F$5:$F$34,4) -> 1362982.1 | F16: =B16-E16 -> 932063.85
A17: 5 | B17: =מחשבון!$B$5*(1+$B$6)^5 -> 2375372.6 | C17: =מחשבון!$B$37*(1+$B$5)^(5-1) -> 81036.634 | D17: =C17-IF(5>מחשבון!$B$8,0,מחשבון!$B$31*12) -> -22102.819 | E17: =INDEX('לוח סילוקין'!$F$5:$F$34,5) -> 1324424.9 | F17: =B17-E17 -> 1050947.7
A18: 6 | B18: =מחשבון!$B$5*(1+$B$6)^6 -> 2458510.7 | C18: =מחשבון!$B$37*(1+$B$5)^(6-1) -> 83467.733 | D18: =C18-IF(6>מחשבון!$B$8,0,מחשבון!$B$31*12) -> -19671.72 | E18: =INDEX('לוח סילוקין'!$F$5:$F$34,6) -> 1283975.7 | F18: =B18-E18 -> 1174535
A19: 7 | B19: =מחשבון!$B$5*(1+$B$6)^7 -> 2544558.5 | C19: =מחשבון!$B$37*(1+$B$5)^(7-1) -> 85971.765 | D19: =C19-IF(7>מחשבון!$B$8,0,מחשבון!$B$31*12) -> -17167.688 | E19: =INDEX('לוח סילוקין'!$F$5:$F$34,7) -> 1241541.6 | F19: =B19-E19 -> 1303016.9
A20: 8 | B20: =מחשבון!$B$5*(1+$B$6)^8 -> 2633618.1 | C20: =מחשבון!$B$37*(1+$B$5)^(8-1) -> 88550.918 | D20: =C20-IF(8>מחשבון!$B$8,0,מחשבון!$B$31*12) -> -14588.535 | E20: =INDEX('לוח סילוקין'!$F$5:$F$34,8) -> 1197025.2 | F20: =B20-E20 -> 1436592.8
A21: 9 | B21: =מחשבון!$B$5*(1+$B$6)^9 -> 2725794.7 | C21: =מחשבון!$B$37*(1+$B$5)^(9-1) -> 91207.446 | D21: =C21-IF(9>מחשבון!$B$8,0,מחשבון!$B$31*12) -> -11932.007 | E21: =INDEX('לוח סילוקין'!$F$5:$F$34,9) -> 1150324.5 | F21: =B21-E21 -> 1575470.2
A22: 10 | B22: =מחשבון!$B$5*(1+$B$6)^10 -> 2821197.5 | C22: =מחשבון!$B$37*(1+$B$5)^(10-1) -> 93943.669 | D22: =C22-IF(10>מחשבון!$B$8,0,מחשבון!$B$31*12) -> -9195.7839 | E22: =INDEX('לוח סילוקין'!$F$5:$F$34,10) -> 1101332.1 | F22: =B22-E22 -> 1719865.5
A23: 11 | B23: =מחשבון!$B$5*(1+$B$6)^11 -> 2919939.4 | C23: =מחשבון!$B$37*(1+$B$5)^(11-1) -> 96761.979 | D23: =C23-IF(11>מחשבון!$B$8,0,מחשבון!$B$31*12) -> -6377.4739 | E23: =INDEX('לוח סילוקין'!$F$5:$F$34,11) -> 1049935.6 | F23: =B23-E23 -> 1870003.8
A24: 12 | B24: =מחשבון!$B$5*(1+$B$6)^12 -> 3022137.3 | C24: =מחשבון!$B$37*(1+$B$5)^(12-1) -> 99664.839 | D24: =C24-IF(12>מחשבון!$B$8,0,מחשבון!$B$31*12) -> -3474.6145 | E24: =INDEX('לוח סילוקין'!$F$5:$F$34,12) -> 996017.12 | F24: =B24-E24 -> 2026120.2
A25: 13 | B25: =מחשבון!$B$5*(1+$B$6)^13 -> 3127912.1 | C25: =מחשבון!$B$37*(1+$B$5)^(13-1) -> 102654.78 | D25: =C25-IF(13>מחשבון!$B$8,0,מחשבון!$B$31*12) -> -484.66932 | E25: =INDEX('לוח סילוקין'!$F$5:$F$34,13) -> 939452.84 | F25: =B25-E25 -> 2188459.3
A26: 14 | B26: =מחשבון!$B$5*(1+$B$6)^14 -> 3237389 | C26: =מחשבון!$B$37*(1+$B$5)^(14-1) -> 105734.43 | D26: =C26-IF(14>מחשבון!$B$8,0,מחשבון!$B$31*12) -> 2594.9742 | E26: =INDEX('לוח סילוקין'!$F$5:$F$34,14) -> 880112.93 | F26: =B26-E26 -> 2357276.1
A27: 15 | B27: =מחשבון!$B$5*(1+$B$6)^15 -> 3350697.7 | C27: =מחשבון!$B$37*(1+$B$5)^(15-1) -> 108906.46 | D27: =C27-IF(15>מחשבון!$B$8,0,מחשבון!$B$31*12) -> 5767.007 | E27: =INDEX('לוח סילוקין'!$F$5:$F$34,15) -> 817861.21 | F27: =B27-E27 -> 2532836.5
A28: 16 | B28: =מחשבון!$B$5*(1+$B$6)^16 -> 3467972.1 | C28: =מחשבון!$B$37*(1+$B$5)^(16-1) -> 112173.65 | D28: =C28-IF(16>מחשבון!$B$8,0,מחשבון!$B$31*12) -> 9034.2008 | E28: =INDEX('לוח סילוקין'!$F$5:$F$34,16) -> 752554.78 | F28: =B28-E28 -> 2715417.3
A29: 17 | B29: =מחשבון!$B$5*(1+$B$6)^17 -> 3589351.1 | C29: =מחשבון!$B$37*(1+$B$5)^(17-1) -> 115538.86 | D29: =C29-IF(17>מחשבון!$B$8,0,מחשבון!$B$31*12) -> 12399.41 | E29: =INDEX('לוח סילוקין'!$F$5:$F$34,17) -> 684043.75 | F29: =B29-E29 -> 2905307.4
A30: 18 | B30: =מחשבון!$B$5*(1+$B$6)^18 -> 3714978.4 | C30: =מחשבון!$B$37*(1+$B$5)^(18-1) -> 119005.03 | D30: =C30-IF(18>מחשבון!$B$8,0,מחשבון!$B$31*12) -> 15865.576 | E30: =INDEX('לוח סילוקין'!$F$5:$F$34,18) -> 612170.87 | F30: =B30-E30 -> 3102807.5
A31: 19 | B31: =מחשבון!$B$5*(1+$B$6)^19 -> 3845002.6 | C31: =מחשבון!$B$37*(1+$B$5)^(19-1) -> 122575.18 | D31: =C31-IF(19>מחשבון!$B$8,0,מחשבון!$B$31*12) -> 19435.727 | E31: =INDEX('לוח סילוקין'!$F$5:$F$34,19) -> 536771.17 | F31: =B31-E31 -> 3308231.5
A32: 20 | B32: =מחשבון!$B$5*(1+$B$6)^20 -> 3979577.7 | C32: =מחשבון!$B$37*(1+$B$5)^(20-1) -> 126252.44 | D32: =C32-IF(20>מחשבון!$B$8,0,מחשבון!$B$31*12) -> 23112.983 | E32: =INDEX('לוח סילוקין'!$F$5:$F$34,20) -> 457671.59 | F32: =B32-E32 -> 3521906.1
A33: 21 | B33: =מחשבון!$B$5*(1+$B$6)^21 -> 4118862.9 | C33: =מחשבון!$B$37*(1+$B$5)^(21-1) -> 130040.01 | D33: =C33-IF(21>מחשבון!$B$8,0,מחשבון!$B$31*12) -> 26900.556 | E33: =INDEX('לוח סילוקין'!$F$5:$F$34,21) -> 374690.58 | F33: =B33-E33 -> 3744172.4
A34: 22 | B34: =מחשבון!$B$5*(1+$B$6)^22 -> 4263023.2 | C34: =מחשבון!$B$37*(1+$B$5)^(22-1) -> 133941.21 | D34: =C34-IF(22>מחשבון!$B$8,0,מחשבון!$B$31*12) -> 30801.756 | E34: =INDEX('לוח סילוקין'!$F$5:$F$34,22) -> 287637.68 | F34: =B34-E34 -> 3975385.5
A35: 23 | B35: =מחשבון!$B$5*(1+$B$6)^23 -> 4412229 | C35: =מחשבון!$B$37*(1+$B$5)^(23-1) -> 137959.45 | D35: =C35-IF(23>מחשבון!$B$8,0,מחשבון!$B$31*12) -> 34819.992 | E35: =INDEX('לוח סילוקין'!$F$5:$F$34,23) -> 196313.07 | F35: =B35-E35 -> 4215915.9
A36: 24 | B36: =מחשבון!$B$5*(1+$B$6)^24 -> 4566657 | C36: =מחשבון!$B$37*(1+$B$5)^(24-1) -> 142098.23 | D36: =C36-IF(24>מחשבון!$B$8,0,מחשבון!$B$31*12) -> 38958.776 | E36: =INDEX('לוח סילוקין'!$F$5:$F$34,24) -> 100507.14 | F36: =B36-E36 -> 4466149.8
A37: 25 | B37: =מחשבון!$B$5*(1+$B$6)^25 -> 4726490 | C37: =מחשבון!$B$37*(1+$B$5)^(25-1) -> 146361.18 | D37: =C37-IF(25>מחשבון!$B$8,0,מחשבון!$B$31*12) -> 43221.722 | E37: =INDEX('לוח סילוקין'!$F$5:$F$34,25) -> 0 | F37: =B37-E37 -> 4726490
A38: 26 | B38: =מחשבון!$B$5*(1+$B$6)^26 -> 4891917.1 | C38: =מחשבון!$B$37*(1+$B$5)^(26-1) -> 150752.01 | D38: =C38-IF(26>מחשבון!$B$8,0,מחשבון!$B$31*12) -> 150752.01 | E38: =INDEX('לוח סילוקין'!$F$5:$F$34,26) -> 0 | F38: =B38-E38 -> 4891917.1
A39: 27 | B39: =מחשבון!$B$5*(1+$B$6)^27 -> 5063134.2 | C39: =מחשבון!$B$37*(1+$B$5)^(27-1) -> 155274.57 | D39: =C39-IF(27>מחשבון!$B$8,0,מחשבון!$B$31*12) -> 155274.57 | E39: =INDEX('לוח סילוקין'!$F$5:$F$34,27) -> 0 | F39: =B39-E39 -> 5063134.2
A40: 28 | B40: =מחשבון!$B$5*(1+$B$6)^28 -> 5240343.9 | C40: =מחשבון!$B$37*(1+$B$5)^(28-1) -> 159932.81 | D40: =C40-IF(28>מחשבון!$B$8,0,מחשבון!$B$31*12) -> 159932.81 | E40: =INDEX('לוח סילוקין'!$F$5:$F$34,28) -> 0 | F40: =B40-E40 -> 5240343.9
A41: 29 | B41: =מחשבון!$B$5*(1+$B$6)^29 -> 5423756 | C41: =מחשבון!$B$37*(1+$B$5)^(29-1) -> 164730.79 | D41: =C41-IF(29>מחשבון!$B$8,0,מחשבון!$B$31*12) -> 164730.79 | E41: =INDEX('לוח סילוקין'!$F$5:$F$34,29) -> 0 | F41: =B41-E41 -> 5423756
A42: 30 | B42: =מחשבון!$B$5*(1+$B$6)^30 -> 5613587.4 | C42: =מחשבון!$B$37*(1+$B$5)^(30-1) -> 169672.72 | D42: =C42-IF(30>מחשבון!$B$8,0,מחשבון!$B$31*12) -> 169672.72 | E42: =INDEX('לוח סילוקין'!$F$5:$F$34,30) -> 0 | F42: =B42-E42 -> 5613587.4
...

Sheet השוואת דירות
A1: השוואה בין דירות
A2: מלא נתונים לכל דירה בעמודות. התוצאות מתחשבות אוטומטית.
A4: פרמטר | B4: דירה 1 | C4: דירה 2 | D4: דירה 3 | E4: דירה 4
A5: מחיר הדירה (₪) | B5: 1800000 | C5: 2200000 | D5: 2600000 | E5: 3000000
A6: סוג רכישה | B6: דירה להשקעה | C6: דירה להשקעה | D6: דירה להשקעה | E6: דירה להשקעה
A7: אחוז מימון רצוי | B7: 0.5 | C7: 0.5 | D7: 0.5 | E7: 0.5
A8: תקופת משכנתא (שנים) | B8: 25 | C8: 25 | D8: 25 | E8: 25
A9: ריבית שנתית | B9: 0.048 | C9: 0.048 | D9: 0.048 | E9: 0.048
A10: שכר דירה חודשי (₪) | B10: 6000 | C10: 7000 | D10: 8200 | E10: 9500
A11: תיווך % | B11: 0.02 | C11: 0.02 | D11: 0.02 | E11: 0.02
A12: שכ"ט עו"ד % | B12: 0.005 | C12: 0.005 | D12: 0.005 | E12: 0.005
A14: 🔹 תוצאות
A15: מס רכישה | B15: =IF(B6="דירה להשקעה",MAX(0,MIN(B5,נתונים!$B$13)-נתונים!$A$13)*נתונים!$C$13+MAX(0,MIN(B5,נתונים!$B$14)-נתונים!$A$14)*נתונים!$C$14,MAX(0,MIN(B5,נתונים!$B$6)-נתונים!$A$6)*נתונים!$C$6+MAX(0,MIN(B5,נתונים!$B$7)-נתונים!$A$7)*נתונים!$C$7+MAX(0,MIN(B5,נתונים!$B$8)-נתונים!$A$8)*נתונים!$C$8+MAX(0,MIN(B5,נתונים!$B$9)-נתונים!$A$9)*נתונים!$C$9) -> 144000 | C15: =IF(C6="דירה להשקעה",MAX(0,MIN(C5,נתונים!$B$13)-נתונים!$A$13)*נתונים!$C$13+MAX(0,MIN(C5,נתונים!$B$14)-נתונים!$A$14)*נתונים!$C$14,MAX(0,MIN(C5,נתונים!$B$6)-נתונים!$A$6)*נתונים!$C$6+MAX(0,MIN(C5,נתונים!$B$7)-נתונים!$A$7)*נתונים!$C$7+MAX(0,MIN(C5,נתונים!$B$8)-נתונים!$A$8)*נתונים!$C$8+MAX(0,MIN(C5,נתונים!$B$9)-נתונים!$A$9)*נתונים!$C$9) -> 176000 | D15: =IF(D6="דירה להשקעה",MAX(0,MIN(D5,נתונים!$B$13)-נתונים!$A$13)*נתונים!$C$13+MAX(0,MIN(D5,נתונים!$B$14)-נתונים!$A$14)*נתונים!$C$14,MAX(0,MIN(D5,נתונים!$B$6)-נתונים!$A$6)*נתונים!$C$6+MAX(0,MIN(D5,נתונים!$B$7)-נתונים!$A$7)*נתונים!$C$7+MAX(0,MIN(D5,נתונים!$B$8)-נתונים!$A$8)*נתונים!$C$8+MAX(0,MIN(D5,נתונים!$B$9)-נתונים!$A$9)*נתונים!$C$9) -> 208000 | E15: =IF(E6="דירה להשקעה",MAX(0,MIN(E5,נתונים!$B$13)-נתונים!$A$13)*נתונים!$C$13+MAX(0,MIN(E5,נתונים!$B$14)-נתונים!$A$14)*נתונים!$C$14,MAX(0,MIN(E5,נתונים!$B$6)-נתונים!$A$6)*נתונים!$C$6+MAX(0,MIN(E5,נתונים!$B$7)-נתונים!$A$7)*נתונים!$C$7+MAX(0,MIN(E5,נתונים!$B$8)-נתונים!$A$8)*נתונים!$C$8+MAX(0,MIN(E5,נתונים!$B$9)-נתונים!$A$9)*נתונים!$C$9) -> 240000
A16: עלויות נלוות (מס+תיווך+עו"ד) | B16: =B15+B5*B11*1.18+B5*B12*1.18 -> 197100 | C16: =C15+C5*C11*1.18+C5*C12*1.18 -> 240900 | D16: =D15+D5*D11*1.18+D5*D12*1.18 -> 284700 | E16: =E15+E5*E11*1.18+E5*E12*1.18 -> 328500
A17: תקרת מימון | B17: =IF(B6="דירה להשקעה",נתונים!$B$19,IF(B6="משפר דיור",נתונים!$B$18,נתונים!$B$17)) -> 0.5 | C17: =IF(C6="דירה להשקעה",נתונים!$B$19,IF(C6="משפר דיור",נתונים!$B$18,נתונים!$B$17)) -> 0.5 | D17: =IF(D6="דירה להשקעה",נתונים!$B$19,IF(D6="משפר דיור",נתונים!$B$18,נתונים!$B$17)) -> 0.5 | E17: =IF(E6="דירה להשקעה",נתונים!$B$19,IF(E6="משפר דיור",נתונים!$B$18,נתונים!$B$17)) -> 0.5
A18: סכום משכנתא | B18: =B5*MIN(B7,B17) -> 900000 | C18: =C5*MIN(C7,C17) -> 1100000 | D18: =D5*MIN(D7,D17) -> 1300000 | E18: =E5*MIN(E7,E17) -> 1500000
A19: הון עצמי נדרש | B19: =B5-B18+B16 -> 1097100 | C19: =C5-C18+C16 -> 1340900 | D19: =D5-D18+D16 -> 1584700 | E19: =E5-E18+E16 -> 1828500
A20: החזר חודשי | B20: =IF(B18>0,PMT(B9/12,B8*12,-B18),0) -> 5156.9727 | C20: =IF(C18>0,PMT(C9/12,C8*12,-C18),0) -> 6302.9666 | D20: =IF(D18>0,PMT(D9/12,D8*12,-D18),0) -> 7448.9605 | E20: =IF(E18>0,PMT(E9/12,E8*12,-E18),0) -> 8594.9544
A21: תשואה ברוטו (על המחיר) | B21: =IF(B5>0,B10*12/B5,0) -> 0.04 | C21: =IF(C5>0,C10*12/C5,0) -> 0.038181818 | D21: =IF(D5>0,D10*12/D5,0) -> 0.037846154 | E21: =IF(E5>0,E10*12/E5,0) -> 0.038
A22: תזרים חודשי נטו | B22: =B10-B20 -> 843.02734 | C22: =C10-C20 -> 697.03342 | D22: =D10-D20 -> 751.03949 | E22: =E10-E20 -> 905.04557
A23: תשואה על ההון (Cash-on-Cash) | B23: =IF(B19>0,(B10-B20)*12/B19,0) -> 0.0092209717 | C23: =IF(C19>0,(C10-C20)*12/C19,0) -> 0.0062379007 | D23: =IF(D19>0,(D10-D20)*12/D19,0) -> 0.0056871799 | E23: =IF(E19>0,(E10-E20)*12/E19,0) -> 0.0059395936

Sheet ניתוח רגישות
A1: ניתוח רגישות
A2: כיצד ההחזר והתשואה משתנים. מבוסס על נתוני גיליון 'מחשבון'.
A4: החזר חודשי לפי ריבית (שורות) × תקופה (עמודות)
A5: ריבית\שנים | B5: 15 | C5: 20 | D5: 25 | E5: 30
A6: 0.03 | B6: =IF(מחשבון!$B$29>0,PMT($A6/12,15*12,-מחשבון!$B$29),0) -> 10358.725 | C6: =IF(מחשבון!$B$29>0,PMT($A6/12,20*12,-מחשבון!$B$29),0) -> 8318.964 | D6: =IF(מחשבון!$B$29>0,PMT($A6/12,25*12,-מחשבון!$B$29),0) -> 7113.1697 | E6: =IF(מחשבון!$B$29>0,PMT($A6/12,30*12,-מחשבון!$B$29),0) -> 6324.0605
A7: 0.035 | B7: =IF(מחשבון!$B$29>0,PMT($A7/12,15*12,-מחשבון!$B$29),0) -> 10723.238 | C7: =IF(מחשבון!$B$29>0,PMT($A7/12,20*12,-מחשבון!$B$29),0) -> 8699.3958 | D7: =IF(מחשבון!$B$29>0,PMT($A7/12,25*12,-מחשבון!$B$29),0) -> 7509.3536 | E7: =IF(מחשבון!$B$29>0,PMT($A7/12,30*12,-מחשבון!$B$29),0) -> 6735.6703
A8: 0.04 | B8: =IF(מחשבון!$B$29>0,PMT($A8/12,15*12,-מחשבון!$B$29),0) -> 11095.319 | C8: =IF(מחשבון!$B$29>0,PMT($A8/12,20*12,-מחשבון!$B$29),0) -> 9089.7049 | D8: =IF(מחשבון!$B$29>0,PMT($A8/12,25*12,-מחשבון!$B$29),0) -> 7917.5526 | E8: =IF(מחשבון!$B$29>0,PMT($A8/12,30*12,-מחשבון!$B$29),0) -> 7161.2294
A9: 0.045 | B9: =IF(מחשבון!$B$29>0,PMT($A9/12,15*12,-מחשבון!$B$29),0) -> 11474.899 | C9: =IF(מחשבון!$B$29>0,PMT($A9/12,20*12,-מחשבון!$B$29),0) -> 9489.7406 | D9: =IF(מחשבון!$B$29>0,PMT($A9/12,25*12,-מחשבון!$B$29),0) -> 8337.4872 | E9: =IF(מחשבון!$B$29>0,PMT($A9/12,30*12,-מחשבון!$B$29),0) -> 7600.2796
A10: 0.05 | B10: =IF(מחשבון!$B$29>0,PMT($A10/12,15*12,-מחשבון!$B$29),0) -> 11861.904 | C10: =IF(מחשבון!$B$29>0,PMT($A10/12,20*12,-מחשבון!$B$29),0) -> 9899.3361 | D10: =IF(מחשבון!$B$29>0,PMT($A10/12,25*12,-מחשבון!$B$29),0) -> 8768.8506 | E10: =IF(מחשבון!$B$29>0,PMT($A10/12,30*12,-מחשבון!$B$29),0) -> 8052.3243
A11: 0.055 | B11: =IF(מחשבון!$B$29>0,PMT($A11/12,15*12,-מחשבון!$B$29),0) -> 12256.252 | C11: =IF(מחשבון!$B$29>0,PMT($A11/12,20*12,-מחשבון!$B$29),0) -> 10318.31 | D11: =IF(מחשבון!$B$29>0,PMT($A11/12,25*12,-מחשבון!$B$29),0) -> 9211.3124 | E11: =IF(מחשבון!$B$29>0,PMT($A11/12,30*12,-מחשבון!$B$29),0) -> 8516.835
A12: 0.06 | B12: =IF(מחשבון!$B$29>0,PMT($A12/12,15*12,-מחשבון!$B$29),0) -> 12657.852 | C12: =IF(מחשבון!$B$29>0,PMT($A12/12,20*12,-מחשבון!$B$29),0) -> 10746.466 | D12: =IF(מחשבון!$B$29>0,PMT($A12/12,25*12,-מחשבון!$B$29),0) -> 9664.521 | E12: =IF(מחשבון!$B$29>0,PMT($A12/12,30*12,-מחשבון!$B$29),0) -> 8993.2579
A13: 0.065 | B13: =IF(מחשבון!$B$29>0,PMT($A13/12,15*12,-מחשבון!$B$29),0) -> 13066.61 | C13: =IF(מחשבון!$B$29>0,PMT($A13/12,20*12,-מחשבון!$B$29),0) -> 11183.597 | D13: =IF(מחשבון!$B$29>0,PMT($A13/12,25*12,-מחשבון!$B$29),0) -> 10128.107 | E13: =IF(מחשבון!$B$29>0,PMT($A13/12,30*12,-מחשבון!$B$29),0) -> 9481.0204
A16: תשואה ברוטו לפי מחיר (שורות) × שכר דירה חודשי (עמודות)
A17: מחיר\שכ"ד | B17: 5000 | C17: 6000 | D17: 7000 | E17: 8000
A18: =מחשבון!$B$5*0.85 -> 1700000 | B18: =IF($A18>0,5000*12/$A18,0) -> 0.035294118 | C18: =IF($A18>0,6000*12/$A18,0) -> 0.042352941 | D18: =IF($A18>0,7000*12/$A18,0) -> 0.049411765 | E18: =IF($A18>0,8000*12/$A18,0) -> 0.056470588
A19: =מחשבון!$B$5*0.9 -> 1800000 | B19: =IF($A19>0,5000*12/$A19,0) -> 0.033333333 | C19: =IF($A19>0,6000*12/$A19,0) -> 0.04 | D19: =IF($A19>0,7000*12/$A19,0) -> 0.046666667 | E19: =IF($A19>0,8000*12/$A19,0) -> 0.053333333
A20: =מחשבון!$B$5*0.95 -> 1900000 | B20: =IF($A20>0,5000*12/$A20,0) -> 0.031578947 | C20: =IF($A20>0,6000*12/$A20,0) -> 0.037894737 | D20: =IF($A20>0,7000*12/$A20,0) -> 0.044210526 | E20: =IF($A20>0,8000*12/$A20,0) -> 0.050526316
A21: =מחשבון!$B$5*1 -> 2000000 | B21: =IF($A21>0,5000*12/$A21,0) -> 0.03 | C21: =IF($A21>0,6000*12/$A21,0) -> 0.036 | D21: =IF($A21>0,7000*12/$A21,0) -> 0.042 | E21: =IF($A21>0,8000*12/$A21,0) -> 0.048
A22: =מחשבון!$B$5*1.05 -> 2100000 | B22: =IF($A22>0,5000*12/$A22,0) -> 0.028571429 | C22: =IF($A22>0,6000*12/$A22,0) -> 0.034285714 | D22: =IF($A22>0,7000*12/$A22,0) -> 0.04 | E22: =IF($A22>0,8000*12/$A22,0) -> 0.045714286
A23: =מחשבון!$B$5*1.1 -> 2200000 | B23: =IF($A23>0,5000*12/$A23,0) -> 0.027272727 | C23: =IF($A23>0,6000*12/$A23,0) -> 0.032727273 | D23: =IF($A23>0,7000*12/$A23,0) -> 0.038181818 | E23: =IF($A23>0,8000*12/$A23,0) -> 0.043636364
A24: =מחשבון!$B$5*1.15 -> 2300000 | B24: =IF($A24>0,5000*12/$A24,0) -> 0.026086957 | C24: =IF($A24>0,6000*12/$A24,0) -> 0.031304348 | D24: =IF($A24>0,7000*12/$A24,0) -> 0.036521739 | E24: =IF($A24>0,8000*12/$A24,0) -> 0.04173913

Sheet ייבוא וסיכום אזור
A1: ייבוא עסקאות וסיכום אזור
A2: הדבק עסקאות שירדו מ-nadlan.gov.il / רשות המסים (החל משורה 16). הסיכום והאומדן מתחשבים אוטומטית.
A4: 🔹 סיכום אזור
A5: מספר עסקאות | B5: =COUNT(G16:G315) -> 3 | D5: מחיר מינימלי | E5: =IF(COUNT(G16:G315)>0,MIN(G16:G315),0) -> 1850000
A6: מחיר ממוצע (₪) | B6: =IF(COUNT(G16:G315)>0,AVERAGE(G16:G315),0) -> 2006666.7 | D6: מחיר מקסימלי | E6: =IF(COUNT(G16:G315)>0,MAX(G16:G315),0) -> 2250000
A7: מחיר חציוני (₪) | B7: =IF(COUNT(G16:G315)>0,MEDIAN(G16:G315),0) -> 1920000 | D7: סטיית תקן | E7: =IF(COUNT(G16:G315)>1,STDEV(G16:G315),0) -> 213619.6
A8: מחיר ממוצע למ"ר (₪) | B8: =IF(SUM(F16:F315)>0,SUM(G16:G315)/SUM(F16:F315),0) -> 23794.466 | D8: ממוצע מ"ר לדירה | E8: =IF(COUNT(F16:F315)>0,AVERAGE(F16:F315),0) -> 84.333333
A10: 🔹 אומדן מחיר לפי שטח
A11: שטח הדירה שמעניין אותך (מ"ר) | B11: 80 | D11: טיפ:
A12: אומדן מחיר (שטח × ממוצע למ"ר) | B12: =B11*B8 -> 1903557.3 | D12: העתק את האומדן לתא B5 בגיליון "מחשבון".
A15: תאריך מכירה | B15: כתובת | C15: שכונה/אזור | D15: סוג נכס | E15: חדרים | F15: שטח (מ"ר) | G15: מחיר עסקה (₪) | H15: מחיר למ"ר
A16: 2026-03-12 | B16: הרצל 15 | C16: מרכז | D16: דירה | E16: 3 | F16: 78 | G16: 1850000 | H16: =IF(F16>0,G16/F16,"") -> 23717.949
A17: 2026-02-08 | B17: ביאליק 4 | C17: מרכז | D17: דירה | E17: 4 | F17: 95 | G17: 2250000 | H17: =IF(F17>0,G17/F17,"") -> 23684.211
A18: 2026-01-20 | B18: ויצמן 30 | C18: צפון | D18: דירה | E18: 3 | F18: 80 | G18: 1920000 | H18: =IF(F18>0,G18/F18,"") -> 24000
H19: =IF(F19>0,G19/F19,"")
H20: =IF(F20>0,G20/F20,"")
H21: =IF(F21>0,G21/F21,"")
H22: =IF(F22>0,G22/F22,"")
H23: =IF(F23>0,G23/F23,"")
H24: =IF(F24>0,G24/F24,"")
H25: =IF(F25>0,G25/F25,"")
H26: =IF(F26>0,G26/F26,"")
H27: =IF(F27>0,G27/F27,"")
H28: =IF(F28>0,G28/F28,"")
H29: =IF(F29>0,G29/F29,"")
H30: =IF(F30>0,G30/F30,"")
... H315: =IF(F315>0,G315/F315,"")

Sheet ניתוח מודעות
A1: מנוע ניתוח מודעות
A2: הדבק נתוני מודעות בעמודות הצהובות (מקור: nadlan.gov.il / מודעות שאתה גולש בהן). השאר מחושב אוטומטית.
A4: 🔹 הנחות לכל הניתוח
A5: סוג רכישה (למס) | B5: דירה להשקעה
A6: אחוז מימון | B6: 0.5
A7: ריבית שנתית | B7: 0.048
A8: תקופת משכנתא (שנים) | B8: 25
A9: תשואה מינ' רצויה (לסימון) | B9: 0.035
A10: מחיר ממוצע למ"ר באזור (₪) | B10: 0
A12: # | B12: כתובת / תיאור | C12: מחיר מבוקש | D12: חדרים | E12: מ"ר | F12: שכ"ד חודשי | G12: מחיר למ"ר | H12: מס רכישה | I12: עלות כוללת | J12: הון עצמי | K12: החזר חודשי | L12: תזרים נטו | M12: תשואה ברוטו | N12: פער ממוצע מ"ר | O12: ציון
A13: 1 | G13: =IF(AND(C13>0,E13>0),C13/E13,"") | H13: =IF(C13>0,IF($B$5="דירה להשקעה",MAX(0,MIN(C13,נתונים!$B$13)-נתונים!$A$13)*נתונים!$C$13+MAX(0,MIN(C13,נתונים!$B$14)-נתונים!$A$14)*נתונים!$C$14,MAX(0,MIN(C13,נתונים!$B$6)-נתונים!$A$6)*נתונים!$C$6+MAX(0,MIN(C13,נתונים!$B$7)-נתונים!$A$7)*נתונים!$C$7+MAX(0,MIN(C13,נתונים!$B$8)-נתונים!$A$8)*נתונים!$C$8+MAX(0,MIN(C13,נתונים!$B$9)-נתונים!$A$9)*נתונים!$C$9),"") | I13: =IF(C13>0,C13+H13+C13*0.02*1.18+C13*0.005*1.18,"") | J13: =IF(C13>0,C13*(1-$B$6)+(I13-C13),"") | K13: =IF(C13>0,PMT($B$7/12,$B$8*12,-C13*$B$6),"") | L13: =IF(C13>0,F13-K13,"") | M13: =IF(AND(C13>0,F13>0),F13*12/C13,"") | N13: =IF(AND($B$10>0,G13<>""),G13/$B$10-1,"") | O13: =IF(C13="","",ROUND(IF(M13<>"",M13*1000,0)+IF(L13>0,2,0)-IF(AND($B$10>0,N13<>""),N13*20,0),1))
A14: 2 | G14: =IF(AND(C14>0,E14>0),C14/E14,"") | H14: =IF(C14>0,IF($B$5="דירה להשקעה",MAX(0,MIN(C14,נתונים!$B$13)-נתונים!$A$13)*נתונים!$C$13+MAX(0,MIN(C14,נתונים!$B$14)-נתונים!$A$14)*נתונים!$C$14,MAX(0,MIN(C14,נתונים!$B$6)-נתונים!$A$6)*נתונים!$C$6+MAX(0,MIN(C14,נתונים!$B$7)-נתונים!$A$7)*נתונים!$C$7+MAX(0,MIN(C14,נתונים!$B$8)-נתונים!$A$8)*נתונים!$C$8+MAX(0,MIN(C14,נתונים!$B$9)-נתונים!$A$9)*נתונים!$C$9),"") | I14: =IF(C14>0,C14+H14+C14*0.02*1.18+C14*0.005*1.18,"") | J14: =IF(C14>0,C14*(1-$B$6)+(I14-C14),"") | K14: =IF(C14>0,PMT($B$7/12,$B$8*12,-C14*$B$6),"") | L14: =IF(C14>0,F14-K14,"") | M14: =IF(AND(C14>0,F14>0),F14*12/C14,"") | N14: =IF(AND($B$10>0,G14<>""),G14/$B$10-1,"") | O14: =IF(C14="","",ROUND(IF(M14<>"",M14*1000,0)+IF(L14>0,2,0)-IF(AND($B$10>0,N14<>""),N14*20,0),1))
A15: 3 | G15: =IF(AND(C15>0,E15>0),C15/E15,"") | H15: =IF(C15>0,IF($B$5="דירה להשקעה",MAX(0,MIN(C15,נתונים!$B$13)-נתונים!$A$13)*נתונים!$C$13+MAX(0,MIN(C15,נתונים!$B$14)-נתונים!$A$14)*נתונים!$C$14,MAX(0,MIN(C15,נתונים!$B$6)-נתונים!$A$6)*נתונים!$C$6+MAX(0,MIN(C15,נתונים!$B$7)-נתונים!$A$7)*נתונים!$C$7+MAX(0,MIN(C15,נתונים!$B$8)-נתונים!$A$8)*נתונים!$C$8+MAX(0,MIN(C15,נתונים!$B$9)-נתונים!$A$9)*נתונים!$C$9),"") | I15: =IF(C15>0,C15+H15+C15*0.02*1.18+C15*0.005*1.18,"") | J15: =IF(C15>0,C15*(1-$B$6)+(I15-C15),"") | K15: =IF(C15>0,PMT($B$7/12,$B$8*12,-C15*$B$6),"") | L15: =IF(C15>0,F15-K15,"") | M15: =IF(AND(C15>0,F15>0),F15*12/C15,"") | N15: =IF(AND($B$10>0,G15<>""),G15/$B$10-1,"") | O15: =IF(C15="","",ROUND(IF(M15<>"",M15*1000,0)+IF(L15>0,2,0)-IF(AND($B$10>0,N15<>""),N15*20,0),1))
A16: 4 | G16: =IF(AND(C16>0,E16>0),C16/E16,"") | H16: =IF(C16>0,IF($B$5="דירה להשקעה",MAX(0,MIN(C16,נתונים!$B$13)-נתונים!$A$13)*נתונים!$C$13+MAX(0,MIN(C16,נתונים!$B$14)-נתונים!$A$14)*נתונים!$C$14,MAX(0,MIN(C16,נתונים!$B$6)-נתונים!$A$6)*נתונים!$C$6+MAX(0,MIN(C16,נתונים!$B$7)-נתונים!$A$7)*נתונים!$C$7+MAX(0,MIN(C16,נתונים!$B$8)-נתונים!$A$8)*נתונים!$C$8+MAX(0,MIN(C16,נתונים!$B$9)-נתונים!$A$9)*נתונים!$C$9),"") | I16: =IF(C16>0,C16+H16+C16*0.02*1.18+C16*0.005*1.18,"") | J16: =IF(C16>0,C16*(1-$B$6)+(I16-C16),"") | K16: =IF(C16>0,PMT($B$7/12,$B$8*12,-C16*$B$6),"") | L16: =IF(C16>0,F16-K16,"") | M16: =IF(AND(C16>0,F16>0),F16*12/C16,"") | N16: =IF(AND($B$10>0,G16<>""),G16/$B$10-1,"") | O16: =IF(C16="","",ROUND(IF(M16<>"",M16*1000,0)+IF(L16>0,2,0)-IF(AND($B$10>0,N16<>""),N16*20,0),1))
A17: 5 | G17: =IF(AND(C17>0,E17>0),C17/E17,"") | H17: =IF(C17>0,IF($B$5="דירה להשקעה",MAX(0,MIN(C17,נתונים!$B$13)-נתונים!$A$13)*נתונים!$C$13+MAX(0,MIN(C17,נתונים!$B$14)-נתונים!$A$14)*נתונים!$C$14,MAX(0,MIN(C17,נתונים!$B$6)-נתונים!$A$6)*נתונים!$C$6+MAX(0,MIN(C17,נתונים!$B$7)-נתונים!$A$7)*נתונים!$C$7+MAX(0,MIN(C17,נתונים!$B$8)-נתונים!$A$8)*נתונים!$C$8+MAX(0,MIN(C17,נתונים!$B$9)-נתונים!$A$9)*נתונים!$C$9),"") | I17: =IF(C17>0,C17+H17+C17*0.02*1.18+C17*0.005*1.18,"") | J17: =IF(C17>0,C17*(1-$B$6)+(I17-C17),"") | K17: =IF(C17>0,PMT($B$7/12,$B$8*12,-C17*$B$6),"") | L17: =IF(C17>0,F17-K17,"") | M17: =IF(AND(C17>0,F17>0),F17*12/C17,"") | N17: =IF(AND($B$10>0,G17<>""),G17/$B$10-1,"") | O17: =IF(C17="","",ROUND(IF(M17<>"",M17*1000,0)+IF(L17>0,2,0)-IF(AND($B$10>0,N17<>""),N17*20,0),1))
A18: 6 | G18: =IF(AND(C18>0,E18>0),C18/E18,"") | H18: =IF(C18>0,IF($B$5="דירה להשקעה",MAX(0,MIN(C18,נתונים!$B$13)-נתונים!$A$13)*נתונים!$C$13+MAX(0,MIN(C18,נתונים!$B$14)-נתונים!$A$14)*נתונים!$C$14,MAX(0,MIN(C18,נתונים!$B$6)-נתונים!$A$6)*נתונים!$C$6+MAX(0,MIN(C18,נתונים!$B$7)-נתונים!$A$7)*נתונים!$C$7+MAX(0,MIN(C18,נתונים!$B$8)-נתונים!$A$8)*נתונים!$C$8+MAX(0,MIN(C18,נתונים!$B$9)-נתונים!$A$9)*נתונים!$C$9),"") | I18: =IF(C18>0,C18+H18+C18*0.02*1.18+C18*0.005*1.18,"") | J18: =IF(C18>0,C18*(1-$B$6)+(I18-C18),"") | K18: =IF(C18>0,PMT($B$7/12,$B$8*12,-C18*$B$6),"") | L18: =IF(C18>0,F18-K18,"") | M18: =IF(AND(C18>0,F18>0),F18*12/C18,"") | N18: =IF(AND($B$10>0,G18<>""),G18/$B$10-1,"") | O18: =IF(C18="","",ROUND(IF(M18<>"",M18*1000,0)+IF(L18>0,2,0)-IF(AND($B$10>0,N18<>""),N18*20,0),1))
A19: 7 | G19: =IF(AND(C19>0,E19>0),C19/E19,"") | H19: =IF(C19>0,IF($B$5="דירה להשקעה",MAX(0,MIN(C19,נתונים!$B$13)-נתונים!$A$13)*נתונים!$C$13+MAX(0,MIN(C19,נתונים!$B$14)-נתונים!$A$14)*נתונים!$C$14,MAX(0,MIN(C19,נתונים!$B$6)-נתונים!$A$6)*נתונים!$C$6+MAX(0,MIN(C19,נתונים!$B$7)-נתונים!$A$7)*נתונים!$C$7+MAX(0,MIN(C19,נתונים!$B$8)-נתונים!$A$8)*נתונים!$C$8+MAX(0,MIN(C19,נתונים!$B$9)-נתונים!$A$9)*נתונים!$C$9),"") | I19: =IF(C19>0,C19+H19+C19*0.02*1.18+C19*0.005*1.18,"") | J19: =IF(C19>0,C19*(1-$B$6)+(I19-C19),"") | K19: =IF(C19>0,PMT($B$7/12,$B$8*12,-C19*$B$6),"") | L19: =IF(C19>0,F19-K19,"") | M19: =IF(AND(C19>0,F19>0),F19*12/C19,"") | N19: =IF(AND($B$10>0,G19<>""),G19/$B$10-1,"") | O19: =IF(C19="","",ROUND(IF(M19<>"",M19*1000,0)+IF(L19>0,2,0)-IF(AND($B$10>0,N19<>""),N19*20,0),1))
A20: 8 | G20: =IF(AND(C20>0,E20>0),C20/E20,"") | H20: =IF(C20>0,IF($B$5="דירה להשקעה",MAX(0,MIN(C20,נתונים!$B$13)-נתונים!$A$13)*נתונים!$C$13+MAX(0,MIN(C20,נתונים!$B$14)-נתונים!$A$14)*נתונים!$C$14,MAX(0,MIN(C20,נתונים!$B$6)-נתונים!$A$6)*נתונים!$C$6+MAX(0,MIN(C20,נתונים!$B$7)-נתונים!$A$7)*נתונים!$C$7+MAX(0,MIN(C20,נתונים!$B$8)-נתונים!$A$8)*נתונים!$C$8+MAX(0,MIN(C20,נתונים!$B$9)-נתונים!$A$9)*נתונים!$C$9),"") | I20: =IF(C20>0,C20+H20+C20*0.02*1.18+C20*0.005*1.18,"") | J20: =IF(C20>0,C20*(1-$B$6)+(I20-C20),"") | K20: =IF(C20>0,PMT($B$7/12,$B$8*12,-C20*$B$6),"") | L20: =IF(C20>0,F20-K20,"") | M20: =IF(AND(C20>0,F20>0),F20*12/C20,"") | N20: =IF(AND($B$10>0,G20<>""),G20/$B$10-1,"") | O20: =IF(C20="","",ROUND(IF(M20<>"",M20*1000,0)+IF(L20>0,2,0)-IF(AND($B$10>0,N20<>""),N20*20,0),1))
A21: 9 | G21: =IF(AND(C21>0,E21>0),C21/E21,"") | H21: =IF(C21>0,IF($B$5="דירה להשקעה",MAX(0,MIN(C21,נתונים!$B$13)-נתונים!$A$13)*נתונים!$C$13+MAX(0,MIN(C21,נתונים!$B$14)-נתונים!$A$14)*נתונים!$C$14,MAX(0,MIN(C21,נתונים!$B$6)-נתונים!$A$6)*נתונים!$C$6+MAX(0,MIN(C21,נתונים!$B$7)-נתונים!$A$7)*נתונים!$C$7+MAX(0,MIN(C21,נתונים!$B$8)-נתונים!$A$8)*נתונים!$C$8+MAX(0,MIN(C21,נתונים!$B$9)-נתונים!$A$9)*נתונים!$C$9),"") | I21: =IF(C21>0,C21+H21+C21*0.02*1.18+C21*0.005*1.18,"") | J21: =IF(C21>0,C21*(1-$B$6)+(I21-C21),"") | K21: =IF(C21>0,PMT($B$7/12,$B$8*12,-C21*$B$6),"") | L21: =IF(C21>0,F21-K21,"") | M21: =IF(AND(C21>0,F21>0),F21*12/C21,"") | N21: =IF(AND($B$10>0,G21<>""),G21/$B$10-1,"") | O21: =IF(C21="","",ROUND(IF(M21<>"",M21*1000,0)+IF(L21>0,2,0)-IF(AND($B$10>0,N21<>""),N21*20,0),1))
A22: 10 | G22: =IF(AND(C22>0,E22>0),C22/E22,"") | H22: =IF(C22>0,IF($B$5="דירה להשקעה",MAX(0,MIN(C22,נתונים!$B$13)-נתונים!$A$13)*נתונים!$C$13+MAX(0,MIN(C22,נתונים!$B$14)-נתונים!$A$14)*נתונים!$C$14,MAX(0,MIN(C22,נתונים!$B$6)-נתונים!$A$6)*נתונים!$C$6+MAX(0,MIN(C22,נתונים!$B$7)-נתונים!$A$7)*נתונים!$C$7+MAX(0,MIN(C22,נתונים!$B$8)-נתונים!$A$8)*נתונים!$C$8+MAX(0,MIN(C22,נתונים!$B$9)-נתונים!$A$9)*נתונים!$C$9),"") | I22: =IF(C22>0,C22+H22+C22*0.02*1.18+C22*0.005*1.18,"") | J22: =IF(C22>0,C22*(1-$B$6)+(I22-C22),"") | K22: =IF(C22>0,PMT($B$7/12,$B$8*12,-C22*$B$6),"") | L22: =IF(C22>0,F22-K22,"") | M22: =IF(AND(C22>0,F22>0),F22*12/C22,"") | N22: =IF(AND($B$10>0,G22<>""),G22/$B$10-1,"") | O22: =IF(C22="","",ROUND(IF(M22<>"",M22*1000,0)+IF(L22>0,2,0)-IF(AND($B$10>0,N22<>""),N22*20,0),1))
A23: 11 | G23: =IF(AND(C23>0,E23>0),C23/E23,"") | H23: =IF(C23>0,IF($B$5="דירה להשקעה",MAX(0,MIN(C23,נתונים!$B$13)-נתונים!$A$13)*נתונים!$C$13+MAX(0,MIN(C23,נתונים!$B$14)-נתונים!$A$14)*נתונים!$C$14,MAX(0,MIN(C23,נתונים!$B$6)-נתונים!$A$6)*נתונים!$C$6+MAX(0,MIN(C23,נתונים!$B$7)-נתונים!$A$7)*נתונים!$C$7+MAX(0,MIN(C23,נתונים!$B$8)-נתונים!$A$8)*נתונים!$C$8+MAX(0,MIN(C23,נתונים!$B$9)-נתונים!$A$9)*נתונים!$C$9),"") | I23: =IF(C23>0,C23+H23+C23*0.02*1.18+C23*0.005*1.18,"") | J23: =IF(C23>0,C23*(1-$B$6)+(I23-C23),"") | K23: =IF(C23>0,PMT($B$7/12,$B$8*12,-C23*$B$6),"") | L23: =IF(C23>0,F23-K23,"") | M23: =IF(AND(C23>0,F23>0),F23*12/C23,"") | N23: =IF(AND($B$10>0,G23<>""),G23/$B$10-1,"") | O23: =IF(C23="","",ROUND(IF(M23<>"",M23*1000,0)+IF(L23>0,2,0)-IF(AND($B$10>0,N23<>""),N23*20,0),1))
A24: 12 | G24: =IF(AND(C24>0,E24>0),C24/E24,"") | H24: =IF(C24>0,IF($B$5="דירה להשקעה",MAX(0,MIN(C24,נתונים!$B$13)-נתונים!$A$13)*נתונים!$C$13+MAX(0,MIN(C24,נתונים!$B$14)-נתונים!$A$14)*נתונים!$C$14,MAX(0,MIN(C24,נתונים!$B$6)-נתונים!$A$6)*נתונים!$C$6+MAX(0,MIN(C24,נתונים!$B$7)-נתונים!$A$7)*נתונים!$C$7+MAX(0,MIN(C24,נתונים!$B$8)-נתונים!$A$8)*נתונים!$C$8+MAX(0,MIN(C24,נתונים!$B$9)-נתונים!$A$9)*נתונים!$C$9),"") | I24: =IF(C24>0,C24+H24+C24*0.02*1.18+C24*0.005*1.18,"") | J24: =IF(C24>0,C24*(1-$B$6)+(I24-C24),"") | K24: =IF(C24>0,PMT($B$7/12,$B$8*12,-C24*$B$6),"") | L24: =IF(C24>0,F24-K24,"") | M24: =IF(AND(C24>0,F24>0),F24*12/C24,"") | N24: =IF(AND($B$10>0,G24<>""),G24/$B$10-1,"") | O24: =IF(C24="","",ROUND(IF(M24<>"",M24*1000,0)+IF(L24>0,2,0)-IF(AND($B$10>0,N24<>""),N24*20,0),1))
... A37: 25 | G37: =IF(AND(C37>0,E37>0),C37/E37,"") | H37: =IF(C37>0,IF($B$5="דירה להשקעה",MAX(0,MIN(C37,נתונים!$B$13)-נתונים!$A$13)*נתונים!$C$13+MAX(0,MIN(C37,נתונים!$B$14)-נתונים!$A$14)*נתונים!$C$14,MAX(0,MIN(C37,נתונים!$B$6)-נתונים!$A$6)*נתונים!$C$6+MAX(0,MIN(C37,נתונים!$B$7)-נתונים!$A$7)*נתונים!$C$7+MAX(0,MIN(C37,נתונים!$B$8)-נתונים!$A$8)*נתונים!$C$8+MAX(0,MIN(C37,נתונים!$B$9)-נתונים!$A$9)*נתונים!$C$9),"") | I37: =IF(C37>0,C37+H37+C37*0.02*1.18+C37*0.005*1.18,"") | J37: =IF(C37>0,C37*(1-$B$6)+(I37-C37),"") | K37: =IF(C37>0,PMT($B$7/12,$B$8*12,-C37*$B$6),"") | L37: =IF(C37>0,F37-K37,"") | M37: =IF(AND(C37>0,F37>0),F37*12/C37,"") | N37: =IF(AND($B$10>0,G37<>""),G37/$B$10-1,"") | O37: =IF(C37="","",ROUND(IF(M37<>"",M37*1000,0)+IF(L37>0,2,0)-IF(AND($B$10>0,N37<>""),N37*20,0),1))
B39: סיכום: | F39: ממוצעים → | G39: =IF(COUNT(G13:G37)>0,AVERAGE(G13:G37),"") | M39: =IF(COUNT(M13:M37)>0,AVERAGE(M13:M37),"")
B40: התשואה הגבוהה ביותר: | M40: =IF(COUNT(M13:M37)>0,MAX(M13:M37),"")
